<?xml version="1.0" ?>
<!-- =================================================================================== -->
<!-- |    This document was autogenerated by xacro from src/zlab_robot_description/urdf/zlab_robot.urdf.xacro | -->
<!-- |    EDITING THIS FILE BY HAND IS NOT RECOMMENDED                                 | -->
<!-- =================================================================================== -->
<robot name="zlab_robot">
  <!-- 顶层结构 -->
  <link name="world"/>
  <joint name="l_joint_base" type="fixed">
    <parent link="world"/>
    <child link="l_base0_link"/>
    <origin rpy="0.0 0.0 0.0" xyz="0.0 0.0 0.0"/>
  </joint>
  <link name="l_base0_link">
    <!-- 惯量属性 -->
    <inertial>
      <origin rpy="0 0 0" xyz="0.00022281 -3.2078E-06 0.11314"/>
      <mass value="50.058"/>
      <inertia ixx="0.87603" ixy="-2.9247e-05" ixz="9.7148e-05" iyy="0.87602" iyz="-1.6883e-06" izz="1.5353"/>
    </inertial>
    <!-- 可视化几何体 -->
    <visual>
      <origin rpy="0 0 0" xyz="0 0 0"/>
      <geometry>
        <mesh filename="package://zlab_robot_description/meshes/collision/extra_base_link.STL" scale="1 1 1"/>
      </geometry>
      <material name="silver">
        <color rgba="0.89804 0.91765 0.92941 1"/>
      </material>
    </visual>
    <!-- 碰撞几何体 -->
    <collision>
      <origin rpy="0 0 0" xyz="0 0 0"/>
      <geometry>
        <mesh filename="package://zlab_robot_description/meshes/collision/extra_base_link.STL" scale="1 1 1"/>
      </geometry>
    </collision>
  </link>
  <link name="l_base1_link">
    <!-- 惯量属性 -->
    <inertial>
      <origin rpy="0 0 0" xyz="2.7756E-16 2.2204E-16 -0.008"/>
      <mass value="3.1592"/>
      <inertia ixx="0.0064529" ixy="-1.9807e-18" ixz="1.3186e-21" iyy="0.0064529" iyz="-1.7017e-21" izz="0.012771"/>
    </inertial>
    <!-- 可视化几何体 -->
    <visual>
      <origin rpy="0 0 0" xyz="0 0 0"/>
      <geometry>
        <mesh filename="package://zlab_robot_description/meshes/collision/plant_link.STL" scale="1 1 1"/>
      </geometry>
      <material name="silver">
        <color rgba="0.89804 0.91765 0.92941 1"/>
      </material>
    </visual>
    <!-- 碰撞几何体 -->
    <collision>
      <origin rpy="0 0 0" xyz="0 0 0"/>
      <geometry>
        <mesh filename="package://zlab_robot_description/meshes/collision/plant_link.STL" scale="1 1 1"/>
      </geometry>
    </collision>
  </link>
  <joint name="l_base0_to_base1" type="fixed">
    <parent link="l_base0_link"/>
    <child link="l_base1_link"/>
    <origin rpy="0 0 0" xyz="0 0 0.487"/>
  </joint>
  <link name="l_base2_link">
    <!-- 惯量属性 -->
    <inertial>
      <origin rpy="0 0 0" xyz="-0.00031896 -0.00029673 0.042463"/>
      <mass value="1.6185"/>
      <inertia ixx="0.0030836" ixy="1.5354e-05" ixz="-1.9315e-05" iyy="0.0030825" iyz="-1.7918e-05" izz="0.0045209"/>
    </inertial>
    <!-- 可视化几何体 -->
    <visual>
      <origin rpy="0 0 0" xyz="0 0 0"/>
      <geometry>
        <mesh filename="package://zlab_robot_description/meshes/visual/base_link.DAE" scale="1 1 1"/>
      </geometry>
      <material name="silver">
        <color rgba="0.89804 0.91765 0.92941 1"/>
      </material>
    </visual>
    <!-- 碰撞几何体 -->
    <collision>
      <origin rpy="0 0 0" xyz="0 0 0"/>
      <geometry>
        <mesh filename="package://zlab_robot_description/meshes/collision/base_link.STL" scale="1 1 1"/>
      </geometry>
    </collision>
  </link>
  <joint name="l_base1_to_base2" type="fixed">
    <parent link="l_base1_link"/>
    <child link="l_base2_link"/>
    <origin rpy="0 0 0" xyz="0 0 0.0001"/>
  </joint>
  <link name="l_j1_link">
    <!-- 惯量属性 -->
    <inertial>
      <origin rpy="0 0 0" xyz="5.0029E-07 -0.0040922 0.14629"/>
      <mass value="4.3771"/>
      <inertia ixx="0.010731" ixy="-8.0587e-09" ixz="-3.6773e-08" iyy="0.010408" iyz="0.00012853" izz="0.0081793"/>
    </inertial>
    <!-- 可视化几何体 -->
    <visual>
      <origin rpy="0 0 0" xyz="0 0 0"/>
      <geometry>
        <mesh filename="package://zlab_robot_description/meshes/visual/j1_link.DAE" scale="1 1 1"/>
      </geometry>
      <material name="silver">
        <color rgba="0.89804 0.91765 0.92941 1"/>
      </material>
    </visual>
    <!-- 碰撞几何体 -->
    <collision>
      <origin rpy="0 0 0" xyz="0 0 0"/>
      <geometry>
        <mesh filename="package://zlab_robot_description/meshes/collision/j1_link.STL" scale="1 1 1"/>
      </geometry>
    </collision>
  </link>
  <joint name="l_j1" type="revolute">
    <origin rpy="0 0 0" xyz="0 0 0"/>
    <parent link="l_base2_link"/>
    <child link="l_j1_link"/>
    <axis xyz="0 0 1"/>
    <limit effort="150" lower="-3.0543" upper="3.0543" velocity="3.15"/>
    <calibration falling="0" rising="0"/>
    <dynamics damping="0" friction="0"/>
    <safety_controller k_position="15" k_velocity="10" soft_lower_limit="-3.0543" soft_upper_limit="3.0543"/>
  </joint>
  <transmission name="trans_l_j1">
    <type>transmission_interface/SimpleTransmission</type>
    <joint name="l_j1">
      <hardwareInterface>hardware_interface/PositionJointInterface</hardwareInterface>
    </joint>
    <actuator name="l_j1_motor">
      <hardwareInterface>hardware_interface/PositionJointInterface</hardwareInterface>
      <mechanicalReduction>1</mechanicalReduction>
    </actuator>
  </transmission>
  <link name="l_j2_link">
    <!-- 惯量属性 -->
    <inertial>
      <origin rpy="0 0 0" xyz="-0.2125 -5.7643E-09 0.1346"/>
      <mass value="14.458"/>
      <inertia ixx="0.028392" ixy="-1.337e-07" ixz="-3.9895e-09" iyy="0.4559" iyz="4.214e-08" izz="0.44974"/>
    </inertial>
    <!-- 可视化几何体 -->
    <visual>
      <origin rpy="0 0 0" xyz="0 0 0"/>
      <geometry>
        <mesh filename="package://zlab_robot_description/meshes/visual/j2_link.DAE" scale="1 1 1"/>
      </geometry>
      <material name="silver">
        <color rgba="0.89804 0.91765 0.92941 1"/>
      </material>
    </visual>
    <!-- 碰撞几何体 -->
    <collision>
      <origin rpy="0 0 0" xyz="0 0 0"/>
      <geometry>
        <mesh filename="package://zlab_robot_description/meshes/collision/j2_link.STL" scale="1 1 1"/>
      </geometry>
    </collision>
  </link>
  <joint name="l_j2" type="revolute">
    <origin rpy="1.5708 0 0" xyz="0 0 0.152"/>
    <parent link="l_j1_link"/>
    <child link="l_j2_link"/>
    <axis xyz="0 0 1"/>
    <limit effort="150" lower="-4.6251" upper="1.4835" velocity="3.15"/>
    <calibration falling="0" rising="0"/>
    <dynamics damping="0" friction="0"/>
    <safety_controller k_position="15" k_velocity="10" soft_lower_limit="-4.6251" soft_upper_limit="1.4835"/>
  </joint>
  <transmission name="trans_l_j2">
    <type>transmission_interface/SimpleTransmission</type>
    <joint name="l_j2">
      <hardwareInterface>hardware_interface/PositionJointInterface</hardwareInterface>
    </joint>
    <actuator name="l_j2_motor">
      <hardwareInterface>hardware_interface/PositionJointInterface</hardwareInterface>
      <mechanicalReduction>1</mechanicalReduction>
    </actuator>
  </transmission>
  <link name="l_j3_link">
    <!-- 惯量属性 -->
    <inertial>
      <origin rpy="0 0 0" xyz="-0.18793 -8.4503E-07 0.0066357"/>
      <mass value="7.6737"/>
      <inertia ixx="0.0085096" ixy="2.1613e-06" ixz="-0.0068678" iyy="0.16971" iyz="3.7086e-08" izz="0.16854"/>
    </inertial>
    <!-- 可视化几何体 -->
    <visual>
      <origin rpy="0 0 0" xyz="0 0 0"/>
      <geometry>
        <mesh filename="package://zlab_robot_description/meshes/visual/j3_link.DAE" scale="1 1 1"/>
      </geometry>
      <material name="silver">
        <color rgba="0.89804 0.91765 0.92941 1"/>
      </material>
    </visual>
    <!-- 碰撞几何体 -->
    <collision>
      <origin rpy="0 0 0" xyz="0 0 0"/>
      <geometry>
        <mesh filename="package://zlab_robot_description/meshes/collision/j3_link.STL" scale="1 1 1"/>
      </geometry>
    </collision>
  </link>
  <joint name="l_j3" type="revolute">
    <origin rpy="0 0 0" xyz="-0.425 0 0"/>
    <parent link="l_j2_link"/>
    <child link="l_j3_link"/>
    <axis xyz="0 0 1"/>
    <limit effort="150" lower="-2.8274" upper="2.8274" velocity="3.15"/>
    <calibration falling="0" rising="0"/>
    <dynamics damping="0" friction="0"/>
    <safety_controller k_position="15" k_velocity="10" soft_lower_limit="-2.8274" soft_upper_limit="2.8274"/>
  </joint>
  <transmission name="trans_l_j3">
    <type>transmission_interface/SimpleTransmission</type>
    <joint name="l_j3">
      <hardwareInterface>hardware_interface/PositionJointInterface</hardwareInterface>
    </joint>
    <actuator name="l_j3_motor">
      <hardwareInterface>hardware_interface/PositionJointInterface</hardwareInterface>
      <mechanicalReduction>1</mechanicalReduction>
    </actuator>
  </transmission>
  <link name="l_j4_link">
    <!-- 惯量属性 -->
    <inertial>
      <origin rpy="0 0 0" xyz="4.98E-07 -0.003754 0.097155"/>
      <mass value="1.6266"/>
      <inertia ixx="0.00216" ixy="4.888e-09" ixz="3.1528e-08" iyy="0.0015455" iyz="3.7678e-05" izz="0.0019902"/>
    </inertial>
    <!-- 可视化几何体 -->
    <visual>
      <origin rpy="0 0 0" xyz="0 0 0"/>
      <geometry>
        <mesh filename="package://zlab_robot_description/meshes/visual/j4_link.DAE" scale="1 1 1"/>
      </geometry>
      <material name="silver">
        <color rgba="0.89804 0.91765 0.92941 1"/>
      </material>
    </visual>
    <!-- 碰撞几何体 -->
    <collision>
      <origin rpy="0 0 0" xyz="0 0 0"/>
      <geometry>
        <mesh filename="package://zlab_robot_description/meshes/collision/j4_link.STL" scale="1 1 1"/>
      </geometry>
    </collision>
  </link>
  <joint name="l_j4" type="revolute">
    <origin rpy="0 0 0" xyz="-0.39501 0 0"/>
    <parent link="l_j3_link"/>
    <child link="l_j4_link"/>
    <axis xyz="0 0 1"/>
    <limit effort="28" lower="-4.6251" upper="1.4835" velocity="3.2"/>
    <calibration falling="0" rising="0"/>
    <dynamics damping="0" friction="0"/>
    <safety_controller k_position="15" k_velocity="10" soft_lower_limit="-4.6251" soft_upper_limit="1.4835"/>
  </joint>
  <transmission name="trans_l_j4">
    <type>transmission_interface/SimpleTransmission</type>
    <joint name="l_j4">
      <hardwareInterface>hardware_interface/PositionJointInterface</hardwareInterface>
    </joint>
    <actuator name="l_j4_motor">
      <hardwareInterface>hardware_interface/PositionJointInterface</hardwareInterface>
      <mechanicalReduction>1</mechanicalReduction>
    </actuator>
  </transmission>
  <link name="l_j5_link">
    <!-- 惯量属性 -->
    <inertial>
      <origin rpy="0 0 0" xyz="-4.5588E-07 0.0038617 0.098257"/>
      <mass value="1.5812"/>
      <inertia ixx="0.0020612" ixy="8.7064e-09" ixz="-3.4742e-08" iyy="0.0014477" iyz="-2.8534e-05" izz="0.0019573"/>
    </inertial>
    <!-- 可视化几何体 -->
    <visual>
      <origin rpy="0 0 0" xyz="0 0 0"/>
      <geometry>
        <mesh filename="package://zlab_robot_description/meshes/visual/j5_link.DAE" scale="1 1 1"/>
      </geometry>
      <material name="silver">
        <color rgba="0.89804 0.91765 0.92941 1"/>
      </material>
    </visual>
    <!-- 碰撞几何体 -->
    <collision>
      <origin rpy="0 0 0" xyz="0 0 0"/>
      <geometry>
        <mesh filename="package://zlab_robot_description/meshes/collision/j5_link.STL" scale="1 1 1"/>
      </geometry>
    </collision>
  </link>
  <joint name="l_j5" type="revolute">
    <origin rpy="1.5708 0 0" xyz="0 0 0.1021"/>
    <parent link="l_j4_link"/>
    <child link="l_j5_link"/>
    <axis xyz="0 0 1"/>
    <limit effort="28" lower="-3.0543" upper="3.0543" velocity="3.2"/>
    <calibration falling="0" rising="0"/>
    <dynamics damping="0" friction="0"/>
    <safety_controller k_position="15" k_velocity="10" soft_lower_limit="-3.0543" soft_upper_limit="3.0543"/>
  </joint>
  <transmission name="trans_l_j5">
    <type>transmission_interface/SimpleTransmission</type>
    <joint name="l_j5">
      <hardwareInterface>hardware_interface/PositionJointInterface</hardwareInterface>
    </joint>
    <actuator name="l_j5_motor">
      <hardwareInterface>hardware_interface/PositionJointInterface</hardwareInterface>
      <mechanicalReduction>1</mechanicalReduction>
    </actuator>
  </transmission>
  <link name="l_j6_link">
    <!-- 惯量属性 -->
    <inertial>
      <origin rpy="0 0 0" xyz="7.7496E-05 1.7751E-05 0.076122"/>
      <mass value="0.52542"/>
      <inertia ixx="0.00027721" ixy="-1.8677e-09" ixz="-1.188e-07" iyy="0.00027839" iyz="2.2607e-07" izz="0.00041605"/>
    </inertial>
    <!-- 可视化几何体 -->
    <visual>
      <origin rpy="0 0 0" xyz="0 0 0"/>
      <geometry>
        <mesh filename="package://zlab_robot_description/meshes/visual/j6_link.DAE" scale="1 1 1"/>
      </geometry>
      <material name="silver">
        <color rgba="0.89804 0.91765 0.92941 1"/>
      </material>
    </visual>
    <!-- 碰撞几何体 -->
    <collision>
      <origin rpy="0 0 0" xyz="0 0 0"/>
      <geometry>
        <mesh filename="package://zlab_robot_description/meshes/collision/j6_link.STL" scale="1 1 1"/>
      </geometry>
    </collision>
  </link>
  <joint name="l_j6" type="revolute">
    <origin rpy="-1.5708 0 0" xyz="0 0 0.102"/>
    <parent link="l_j5_link"/>
    <child link="l_j6_link"/>
    <axis xyz="0 0 1"/>
    <limit effort="28" lower="-3.0543" upper="3.0543" velocity="3.2"/>
    <calibration falling="0" rising="0"/>
    <dynamics damping="0" friction="0"/>
    <safety_controller k_position="15" k_velocity="10" soft_lower_limit="-3.0543" soft_upper_limit="3.0543"/>
  </joint>
  <transmission name="trans_l_j6">
    <type>transmission_interface/SimpleTransmission</type>
    <joint name="l_j6">
      <hardwareInterface>hardware_interface/PositionJointInterface</hardwareInterface>
    </joint>
    <actuator name="l_j6_motor">
      <hardwareInterface>hardware_interface/PositionJointInterface</hardwareInterface>
      <mechanicalReduction>1</mechanicalReduction>
    </actuator>
  </transmission>
  <joint name="r_joint_base" type="fixed">
    <parent link="world"/>
    <child link="r_base0_link"/>
    <origin rpy="0.0 0.0 0.0" xyz="0.0 0.8 0.0"/>
  </joint>
  <link name="r_base0_link">
    <!-- 惯量属性 -->
    <inertial>
      <origin rpy="0 0 0" xyz="0.00022281 -3.2078E-06 0.11314"/>
      <mass value="50.058"/>
      <inertia ixx="0.87603" ixy="-2.9247e-05" ixz="9.7148e-05" iyy="0.87602" iyz="-1.6883e-06" izz="1.5353"/>
    </inertial>
    <!-- 可视化几何体 -->
    <visual>
      <origin rpy="0 0 0" xyz="0 0 0"/>
      <geometry>
        <mesh filename="package://zlab_robot_description/meshes/collision/extra_base_link.STL" scale="1 1 1"/>
      </geometry>
      <material name="silver">
        <color rgba="0.89804 0.91765 0.92941 1"/>
      </material>
    </visual>
    <!-- 碰撞几何体 -->
    <collision>
      <origin rpy="0 0 0" xyz="0 0 0"/>
      <geometry>
        <mesh filename="package://zlab_robot_description/meshes/collision/extra_base_link.STL" scale="1 1 1"/>
      </geometry>
    </collision>
  </link>
  <link name="r_base1_link">
    <!-- 惯量属性 -->
    <inertial>
      <origin rpy="0 0 0" xyz="2.7756E-16 2.2204E-16 -0.008"/>
      <mass value="3.1592"/>
      <inertia ixx="0.0064529" ixy="-1.9807e-18" ixz="1.3186e-21" iyy="0.0064529" iyz="-1.7017e-21" izz="0.012771"/>
    </inertial>
    <!-- 可视化几何体 -->
    <visual>
      <origin rpy="0 0 0" xyz="0 0 0"/>
      <geometry>
        <mesh filename="package://zlab_robot_description/meshes/collision/plant_link.STL" scale="1 1 1"/>
      </geometry>
      <material name="silver">
        <color rgba="0.89804 0.91765 0.92941 1"/>
      </material>
    </visual>
    <!-- 碰撞几何体 -->
    <collision>
      <origin rpy="0 0 0" xyz="0 0 0"/>
      <geometry>
        <mesh filename="package://zlab_robot_description/meshes/collision/plant_link.STL" scale="1 1 1"/>
      </geometry>
    </collision>
  </link>
  <joint name="r_base0_to_base1" type="fixed">
    <parent link="r_base0_link"/>
    <child link="r_base1_link"/>
    <origin rpy="0 0 0" xyz="0 0 0.487"/>
  </joint>
  <link name="r_base2_link">
    <!-- 惯量属性 -->
    <inertial>
      <origin rpy="0 0 0" xyz="-0.00031896 -0.00029673 0.042463"/>
      <mass value="1.6185"/>
      <inertia ixx="0.0030836" ixy="1.5354e-05" ixz="-1.9315e-05" iyy="0.0030825" iyz="-1.7918e-05" izz="0.0045209"/>
    </inertial>
    <!-- 可视化几何体 -->
    <visual>
      <origin rpy="0 0 0" xyz="0 0 0"/>
      <geometry>
        <mesh filename="package://zlab_robot_description/meshes/visual/base_link.DAE" scale="1 1 1"/>
      </geometry>
      <material name="silver">
        <color rgba="0.89804 0.91765 0.92941 1"/>
      </material>
    </visual>
    <!-- 碰撞几何体 -->
    <collision>
      <origin rpy="0 0 0" xyz="0 0 0"/>
      <geometry>
        <mesh filename="package://zlab_robot_description/meshes/collision/base_link.STL" scale="1 1 1"/>
      </geometry>
    </collision>
  </link>
  <joint name="r_base1_to_base2" type="fixed">
    <parent link="r_base1_link"/>
    <child link="r_base2_link"/>
    <origin rpy="0 0 0" xyz="0 0 0.0001"/>
  </joint>
  <link name="r_j1_link">
    <!-- 惯量属性 -->
    <inertial>
      <origin rpy="0 0 0" xyz="5.0029E-07 -0.0040922 0.14629"/>
      <mass value="4.3771"/>
      <inertia ixx="0.010731" ixy="-8.0587e-09" ixz="-3.6773e-08" iyy="0.010408" iyz="0.00012853" izz="0.0081793"/>
    </inertial>
    <!-- 可视化几何体 -->
    <visual>
      <origin rpy="0 0 0" xyz="0 0 0"/>
      <geometry>
        <mesh filename="package://zlab_robot_description/meshes/visual/j1_link.DAE" scale="1 1 1"/>
      </geometry>
      <material name="silver">
        <color rgba="0.89804 0.91765 0.92941 1"/>
      </material>
    </visual>
    <!-- 碰撞几何体 -->
    <collision>
      <origin rpy="0 0 0" xyz="0 0 0"/>
      <geometry>
        <mesh filename="package://zlab_robot_description/meshes/collision/j1_link.STL" scale="1 1 1"/>
      </geometry>
    </collision>
  </link>
  <joint name="r_j1" type="revolute">
    <origin rpy="0 0 0" xyz="0 0 0"/>
    <parent link="r_base2_link"/>
    <child link="r_j1_link"/>
    <axis xyz="0 0 1"/>
    <limit effort="150" lower="-3.0543" upper="3.0543" velocity="3.15"/>
    <calibration falling="0" rising="0"/>
    <dynamics damping="0" friction="0"/>
    <safety_controller k_position="15" k_velocity="10" soft_lower_limit="-3.0543" soft_upper_limit="3.0543"/>
  </joint>
  <transmission name="trans_r_j1">
    <type>transmission_interface/SimpleTransmission</type>
    <joint name="r_j1">
      <hardwareInterface>hardware_interface/PositionJointInterface</hardwareInterface>
    </joint>
    <actuator name="r_j1_motor">
      <hardwareInterface>hardware_interface/PositionJointInterface</hardwareInterface>
      <mechanicalReduction>1</mechanicalReduction>
    </actuator>
  </transmission>
  <link name="r_j2_link">
    <!-- 惯量属性 -->
    <inertial>
      <origin rpy="0 0 0" xyz="-0.2125 -5.7643E-09 0.1346"/>
      <mass value="14.458"/>
      <inertia ixx="0.028392" ixy="-1.337e-07" ixz="-3.9895e-09" iyy="0.4559" iyz="4.214e-08" izz="0.44974"/>
    </inertial>
    <!-- 可视化几何体 -->
    <visual>
      <origin rpy="0 0 0" xyz="0 0 0"/>
      <geometry>
        <mesh filename="package://zlab_robot_description/meshes/visual/j2_link.DAE" scale="1 1 1"/>
      </geometry>
      <material name="silver">
        <color rgba="0.89804 0.91765 0.92941 1"/>
      </material>
    </visual>
    <!-- 碰撞几何体 -->
    <collision>
      <origin rpy="0 0 0" xyz="0 0 0"/>
      <geometry>
        <mesh filename="package://zlab_robot_description/meshes/collision/j2_link.STL" scale="1 1 1"/>
      </geometry>
    </collision>
  </link>
  <joint name="r_j2" type="revolute">
    <origin rpy="1.5708 0 0" xyz="0 0 0.152"/>
    <parent link="r_j1_link"/>
    <child link="r_j2_link"/>
    <axis xyz="0 0 1"/>
    <limit effort="150" lower="-4.6251" upper="1.4835" velocity="3.15"/>
    <calibration falling="0" rising="0"/>
    <dynamics damping="0" friction="0"/>
    <safety_controller k_position="15" k_velocity="10" soft_lower_limit="-4.6251" soft_upper_limit="1.4835"/>
  </joint>
  <transmission name="trans_r_j2">
    <type>transmission_interface/SimpleTransmission</type>
    <joint name="r_j2">
      <hardwareInterface>hardware_interface/PositionJointInterface</hardwareInterface>
    </joint>
    <actuator name="r_j2_motor">
      <hardwareInterface>hardware_interface/PositionJointInterface</hardwareInterface>
      <mechanicalReduction>1</mechanicalReduction>
    </actuator>
  </transmission>
  <link name="r_j3_link">
    <!-- 惯量属性 -->
    <inertial>
      <origin rpy="0 0 0" xyz="-0.18793 -8.4503E-07 0.0066357"/>
      <mass value="7.6737"/>
      <inertia ixx="0.0085096" ixy="2.1613e-06" ixz="-0.0068678" iyy="0.16971" iyz="3.7086e-08" izz="0.16854"/>
    </inertial>
    <!-- 可视化几何体 -->
    <visual>
      <origin rpy="0 0 0" xyz="0 0 0"/>
      <geometry>
        <mesh filename="package://zlab_robot_description/meshes/visual/j3_link.DAE" scale="1 1 1"/>
      </geometry>
      <material name="silver">
        <color rgba="0.89804 0.91765 0.92941 1"/>
      </material>
    </visual>
    <!-- 碰撞几何体 -->
    <collision>
      <origin rpy="0 0 0" xyz="0 0 0"/>
      <geometry>
        <mesh filename="package://zlab_robot_description/meshes/collision/j3_link.STL" scale="1 1 1"/>
      </geometry>
    </collision>
  </link>
  <joint name="r_j3" type="revolute">
    <origin rpy="0 0 0" xyz="-0.425 0 0"/>
    <parent link="r_j2_link"/>
    <child link="r_j3_link"/>
    <axis xyz="0 0 1"/>
    <limit effort="150" lower="-2.8274" upper="2.8274" velocity="3.15"/>
    <calibration falling="0" rising="0"/>
    <dynamics damping="0" friction="0"/>
    <safety_controller k_position="15" k_velocity="10" soft_lower_limit="-2.8274" soft_upper_limit="2.8274"/>
  </joint>
  <transmission name="trans_r_j3">
    <type>transmission_interface/SimpleTransmission</type>
    <joint name="r_j3">
      <hardwareInterface>hardware_interface/PositionJointInterface</hardwareInterface>
    </joint>
    <actuator name="r_j3_motor">
      <hardwareInterface>hardware_interface/PositionJointInterface</hardwareInterface>
      <mechanicalReduction>1</mechanicalReduction>
    </actuator>
  </transmission>
  <link name="r_j4_link">
    <!-- 惯量属性 -->
    <inertial>
      <origin rpy="0 0 0" xyz="4.98E-07 -0.003754 0.097155"/>
      <mass value="1.6266"/>
      <inertia ixx="0.00216" ixy="4.888e-09" ixz="3.1528e-08" iyy="0.0015455" iyz="3.7678e-05" izz="0.0019902"/>
    </inertial>
    <!-- 可视化几何体 -->
    <visual>
      <origin rpy="0 0 0" xyz="0 0 0"/>
      <geometry>
        <mesh filename="package://zlab_robot_description/meshes/visual/j4_link.DAE" scale="1 1 1"/>
      </geometry>
      <material name="silver">
        <color rgba="0.89804 0.91765 0.92941 1"/>
      </material>
    </visual>
    <!-- 碰撞几何体 -->
    <collision>
      <origin rpy="0 0 0" xyz="0 0 0"/>
      <geometry>
        <mesh filename="package://zlab_robot_description/meshes/collision/j4_link.STL" scale="1 1 1"/>
      </geometry>
    </collision>
  </link>
  <joint name="r_j4" type="revolute">
    <origin rpy="0 0 0" xyz="-0.39501 0 0"/>
    <parent link="r_j3_link"/>
    <child link="r_j4_link"/>
    <axis xyz="0 0 1"/>
    <limit effort="28" lower="-4.6251" upper="1.4835" velocity="3.2"/>
    <calibration falling="0" rising="0"/>
    <dynamics damping="0" friction="0"/>
    <safety_controller k_position="15" k_velocity="10" soft_lower_limit="-4.6251" soft_upper_limit="1.4835"/>
  </joint>
  <transmission name="trans_r_j4">
    <type>transmission_interface/SimpleTransmission</type>
    <joint name="r_j4">
      <hardwareInterface>hardware_interface/PositionJointInterface</hardwareInterface>
    </joint>
    <actuator name="r_j4_motor">
      <hardwareInterface>hardware_interface/PositionJointInterface</hardwareInterface>
      <mechanicalReduction>1</mechanicalReduction>
    </actuator>
  </transmission>
  <link name="r_j5_link">
    <!-- 惯量属性 -->
    <inertial>
      <origin rpy="0 0 0" xyz="-4.5588E-07 0.0038617 0.098257"/>
      <mass value="1.5812"/>
      <inertia ixx="0.0020612" ixy="8.7064e-09" ixz="-3.4742e-08" iyy="0.0014477" iyz="-2.8534e-05" izz="0.0019573"/>
    </inertial>
    <!-- 可视化几何体 -->
    <visual>
      <origin rpy="0 0 0" xyz="0 0 0"/>
      <geometry>
        <mesh filename="package://zlab_robot_description/meshes/visual/j5_link.DAE" scale="1 1 1"/>
      </geometry>
      <material name="silver">
        <color rgba="0.89804 0.91765 0.92941 1"/>
      </material>
    </visual>
    <!-- 碰撞几何体 -->
    <collision>
      <origin rpy="0 0 0" xyz="0 0 0"/>
      <geometry>
        <mesh filename="package://zlab_robot_description/meshes/collision/j5_link.STL" scale="1 1 1"/>
      </geometry>
    </collision>
  </link>
  <joint name="r_j5" type="revolute">
    <origin rpy="1.5708 0 0" xyz="0 0 0.1021"/>
    <parent link="r_j4_link"/>
    <child link="r_j5_link"/>
    <axis xyz="0 0 1"/>
    <limit effort="28" lower="-3.0543" upper="3.0543" velocity="3.2"/>
    <calibration falling="0" rising="0"/>
    <dynamics damping="0" friction="0"/>
    <safety_controller k_position="15" k_velocity="10" soft_lower_limit="-3.0543" soft_upper_limit="3.0543"/>
  </joint>
  <transmission name="trans_r_j5">
    <type>transmission_interface/SimpleTransmission</type>
    <joint name="r_j5">
      <hardwareInterface>hardware_interface/PositionJointInterface</hardwareInterface>
    </joint>
    <actuator name="r_j5_motor">
      <hardwareInterface>hardware_interface/PositionJointInterface</hardwareInterface>
      <mechanicalReduction>1</mechanicalReduction>
    </actuator>
  </transmission>
  <link name="r_j6_link">
    <!-- 惯量属性 -->
    <inertial>
      <origin rpy="0 0 0" xyz="7.7496E-05 1.7751E-05 0.076122"/>
      <mass value="0.52542"/>
      <inertia ixx="0.00027721" ixy="-1.8677e-09" ixz="-1.188e-07" iyy="0.00027839" iyz="2.2607e-07" izz="0.00041605"/>
    </inertial>
    <!-- 可视化几何体 -->
    <visual>
      <origin rpy="0 0 0" xyz="0 0 0"/>
      <geometry>
        <mesh filename="package://zlab_robot_description/meshes/visual/j6_link.DAE" scale="1 1 1"/>
      </geometry>
      <material name="silver">
        <color rgba="0.89804 0.91765 0.92941 1"/>
      </material>
    </visual>
    <!-- 碰撞几何体 -->
    <collision>
      <origin rpy="0 0 0" xyz="0 0 0"/>
      <geometry>
        <mesh filename="package://zlab_robot_description/meshes/collision/j6_link.STL" scale="1 1 1"/>
      </geometry>
    </collision>
  </link>
  <joint name="r_j6" type="revolute">
    <origin rpy="-1.5708 0 0" xyz="0 0 0.102"/>
    <parent link="r_j5_link"/>
    <child link="r_j6_link"/>
    <axis xyz="0 0 1"/>
    <limit effort="28" lower="-3.0543" upper="3.0543" velocity="3.2"/>
    <calibration falling="0" rising="0"/>
    <dynamics damping="0" friction="0"/>
    <safety_controller k_position="15" k_velocity="10" soft_lower_limit="-3.0543" soft_upper_limit="3.0543"/>
  </joint>
  <transmission name="trans_r_j6">
    <type>transmission_interface/SimpleTransmission</type>
    <joint name="r_j6">
      <hardwareInterface>hardware_interface/PositionJointInterface</hardwareInterface>
    </joint>
    <actuator name="r_j6_motor">
      <hardwareInterface>hardware_interface/PositionJointInterface</hardwareInterface>
      <mechanicalReduction>1</mechanicalReduction>
    </actuator>
  </transmission>
  <gazebo>
    <plugin filename="libgazebo_ros_control.so" name="gazebo_ros_control"/>
  </gazebo>
</robot>
